2025-09-21 18:07:08,503 - sync_manager - ERROR - Error in background sync process: name 'asyncio' is not defined
Traceback (most recent call last):
  File "E:\billing-app\backend\app.py", line 796, in sync_continuously
    loop.run_until_complete(start_sync_process())
  File "C:\Users\Dell\AppData\Local\Programs\Python\Python312\Lib\asyncio\base_events.py", line 691, in run_until_complete
    return future.result()
           ^^^^^^^^^^^^^^^
  File "E:\billing-app\backend\scripts\sync_check.py", line 348, in start_sync_process
    await run_checks()
  File "E:\billing-app\backend\scripts\sync_check.py", line 345, in run_checks
    await asyncio.sleep(POLLING_INTERVAL) # Use asyncio.sleep for non-blocking wait
          ^^^^^^^
NameError: name 'asyncio' is not defined. Did you forget to import 'asyncio'
